<robot name="Team10">
	<link name="world"/>
	<link name="link0">
		<visual>
			<origin xyz="0 0 0.1" rpy="0 0 0" />
			<geometry>
				<box size="0.6 0.6 0.2"/>
			</geometry>
		</visual>
		<collision>
     		<origin xyz="0 0 0.1" rpy="0 0 0"/>
    			<geometry>
       			<box size="0.6 0.6 0.2"/>
     			</geometry>
   		</collision>
   		<inertial>
			<origin xyz="0 0 0.1" rpy="0 0 0"/>
			<mass value="1"/>
			<inertia ixx="0"  ixy="0"  ixz="0" iyy="0" iyz="0" izz="0" />
		</inertial>
	</link>
	<link name="link1">
		<visual>
			<origin xyz="0 0 0.1" rpy="0 0 0" />
			<geometry>
				<cylinder radius="0.2" length="0.2"/>
			</geometry>
		</visual>
		<collision>
    	<origin xyz="0 0 0.1" rpy="0 0 0"/>
    	<geometry>
    		<cylinder radius="0.2" length="0.16"/>
    	</geometry>
   	</collision>
   	<inertial>
		<origin xyz="0 0 0.1" rpy="0 0 0"/>
		<mass value="1"/>
		<inertia ixx="0"  ixy="0"  ixz="0" iyy="0" iyz="0" izz="0" />
	</inertial>

	</link>
	<link name="link2">
		<visual>
			<origin xyz="0 0 0.3" rpy="0 0 0" />
			<geometry>
				<cylinder radius="0.16" length="0.6"/>
			</geometry>
		</visual>
		<collision>
    	<origin xyz="0 0 0.3" rpy="0 0 0"/>
    	<geometry>
    		<cylinder radius="0.16" length="0.40"/>
    	</geometry>
   	</collision>
   	<inertial>
		<origin xyz="0 0 0.3" rpy="0 0 0"/>
		<mass value="1"/>
		<inertia ixx="0"  ixy="0"  ixz="0" iyy="0" iyz="0" izz="0" />
	</inertial>   	
	</link>
	<link name="link3">
		<visual>
			<origin xyz="0 0 0.175" rpy="0 0 0" />
			<geometry>
				<cylinder radius="0.14" length="0.35"/>
			</geometry>
		</visual>
		<collision>
    	<origin xyz="0 0 0.175" rpy="0 0 0"/>
    	<geometry>
    		<cylinder radius="0.14" length="0.2"/>
    	</geometry>
   	</collision>
   	<inertial>
		<origin xyz="0 0 0.175" rpy="0 0 0"/>
		<mass value="1"/>
		<inertia ixx="0"  ixy="0"  ixz="0" iyy="0" iyz="0" izz="0" />
	</inertial>
	</link>
	<link name="link4">
		<visual>
			<origin xyz="0 0 0.125" rpy="0 0 0" />
			<geometry>
				<cylinder radius="0.12" length="0.25"/>
			</geometry>
		</visual>
		<collision>
    	<origin xyz="0 0 0.125" rpy="0 0 0"/>
    	<geometry>
    		<cylinder radius="0.12" length="0.2"/>
    	</geometry>
   	</collision>
   	<inertial>
		<origin xyz="0 0 0.125" rpy="0 0 0"/>
		<mass value="1"/>
		<inertia ixx="0"  ixy="0"  ixz="0" iyy="0" iyz="0" izz="0" />
	</inertial>
	</link>
	<link name="link5">
		<visual>
			<origin xyz="0 0 0.1" rpy="0 0 0" />
			<geometry>
				<cylinder radius="0.1" length="0.2"/>
			</geometry>
		</visual>
		<collision>
    	<origin xyz="0 0 0.1" rpy="0 0 0"/>
    	<geometry>
    		<cylinder radius="0.1" length="0.1"/>
    	</geometry>
   	</collision>
   	<inertial>
		<origin xyz="0 0 0.1" rpy="0 0 0"/>
		<mass value="1"/>
		<inertia ixx="0"  ixy="0"  ixz="0" iyy="0" iyz="0" izz="0" />
	</inertial>
	</link>	
	<link name="link6">
		<visual>
			<origin xyz="0 0 0.05" rpy="0 0 0" />
			<geometry>
				<box size="0.1 0.1 0.1"/>
			</geometry>
		</visual>
		<collision>
    	<origin xyz="0 0 0.05" rpy="0 0 0"/>
    	<geometry>
    		<box size="0.1 0.1 0.1"/>
    	</geometry>
   	</collision>
   	<inertial>
		<origin xyz="0 0 0.05" rpy="0 0 0"/>
		<mass value="1"/>
		<inertia ixx="0"  ixy="0"  ixz="0" iyy="0" iyz="0" izz="0" />
	</inertial>
	</link>	
		<joint name="jointW0" type="fixed">
			<origin xyz="0 0 0.2" rpy="0 0 0" />
			<parent link="world" />
			<child link ="link0" />
			<axis xyz="0 1 0" />
		</joint>
		<joint name="joint01" type="revolute">
			<origin xyz="0 0 0.2" rpy="0 0 0" />
			<parent link="link0" />
			<child link ="link1" />
			<axis xyz="0 0 1" />
			<limit lower="-3.14" upper="3.14" effort="20" velocity="1" />
		</joint>
		<joint name="joint12" type="revolute">
			<origin xyz="0 0 0.2" rpy="0 0 0" />
			<parent link="link1" />
			<child link ="link2" />
			<axis xyz="0 1 0" />
			<limit lower="-3.14" upper="3.14" effort="20" velocity="1" />
		</joint>
			<joint name="joint23" type="revolute">
			<origin xyz="0 0 0.6" rpy="0 0 0" />
			<parent link="link2" />
			<child link ="link3" />
			<axis xyz="0 1 0" />
			<limit lower="-3.14" upper="3.14" effort="20" velocity="1" />
		</joint>
		<joint name="joint34" type="revolute">
			<origin xyz="0 0 0.35" rpy="0 0 0" />
			<parent link="link3" />
			<child link ="link4" />
			<axis xyz="0 0 1" />
			<limit lower="-3.14" upper="3.14" effort="20" velocity="1" />
		</joint>
		<joint name="joint45" type="revolute">
			<origin xyz="0 0 0.25" rpy="0 0 0" />
			<parent link="link4" />
			<child link ="link5" />
			<axis xyz="0 1 0" />
			<limit lower="-3.14" upper="3.14" effort="20" velocity="1" />
		</joint>
		<joint name="joint56" type="revolute">
			<origin xyz="0 0 0.2" rpy="0 0 0" />
			<parent link="link5" />
			<child link ="link6" />
			<axis xyz="0 1 0" />
			<limit lower="-3.14" upper="3.14" effort="20" velocity="1" />
		</joint>
<transmission name="trans01">
  <type>transmission_interface/SimpleTransmission</type>
  <joint name="joint01">
    <hardwareInterface>hardware_interface/PositionJointInterface</hardwareInterface>
  </joint>
  <actuator name="motor01">
    <mechanicalReduction>1</mechanicalReduction>
    <hardwareInterface>hardware_interface/PositionJointInterface</hardwareInterface>
  </actuator>
</transmission>
<transmission name="trans12">
  <type>transmission_interface/SimpleTransmission</type>
  <joint name="joint12">
    <hardwareInterface>hardware_interface/PositionJointInterface</hardwareInterface>
  </joint>
  <actuator name="motor12">
    <mechanicalReduction>1</mechanicalReduction>
    <hardwareInterface>hardware_interface/PositionJointInterface</hardwareInterface>
  </actuator>
</transmission>
<transmission name="trans23">
  <type>transmission_interface/SimpleTransmission</type>
  <joint name="joint23">
    <hardwareInterface>hardware_interface/PositionJointInterface</hardwareInterface>
  </joint>
  <actuator name="motor23">
    <mechanicalReduction>1</mechanicalReduction>
    <hardwareInterface>hardware_interface/PositionJointInterface</hardwareInterface>
  </actuator>
</transmission>
<transmission name="trans34">
  <type>transmission_interface/SimpleTransmission</type>
  <joint name="joint34">
    <hardwareInterface>hardware_interface/PositionJointInterface</hardwareInterface>
  </joint>
  <actuator name="motor34">
    <mechanicalReduction>1</mechanicalReduction>
    <hardwareInterface>hardware_interface/PositionJointInterface</hardwareInterface>
  </actuator>
</transmission>
<transmission name="trans45">
  <type>transmission_interface/SimpleTransmission</type>
  <joint name="joint45">
    <hardwareInterface>hardware_interface/PositionJointInterface</hardwareInterface>
  </joint>
  <actuator name="motor45">
    <mechanicalReduction>1</mechanicalReduction>
    <hardwareInterface>hardware_interface/PositionJointInterface</hardwareInterface>
  </actuator>
</transmission>
<transmission name="trans56">
  <type>transmission_interface/SimpleTransmission</type>
  <joint name="joint56">
    <hardwareInterface>hardware_interface/PositionJointInterface</hardwareInterface>
  </joint>
  <actuator name="motor56">
    <mechanicalReduction>1</mechanicalReduction>
    <hardwareInterface>hardware_interface/PositionJointInterface</hardwareInterface>
  </actuator>
</transmission>
<gazebo>
  <plugin name="gazebo_ros_control" filename="libgazebo_ros_control.so">
    <robotNamespace>/asu_controller</robotNamespace>
    <legacyModeNS>true</legacyModeNS>
  </plugin>
</gazebo>
</robot>
